[2024-05-06 07:41:01,162] {taskinstance.py:851} INFO - Dependencies all met for <TaskInstance: dag_with_prostgres_hooks_v2.poastgres_to_s3 2024-05-05T00:00:00+00:00 [queued]>
[2024-05-06 07:41:01,188] {taskinstance.py:851} INFO - Dependencies all met for <TaskInstance: dag_with_prostgres_hooks_v2.poastgres_to_s3 2024-05-05T00:00:00+00:00 [queued]>
[2024-05-06 07:41:01,189] {taskinstance.py:1042} INFO - 
--------------------------------------------------------------------------------
[2024-05-06 07:41:01,190] {taskinstance.py:1043} INFO - Starting attempt 1 of 6
[2024-05-06 07:41:01,190] {taskinstance.py:1044} INFO - 
--------------------------------------------------------------------------------
[2024-05-06 07:41:01,209] {taskinstance.py:1063} INFO - Executing <Task(PythonOperator): poastgres_to_s3> on 2024-05-05T00:00:00+00:00
[2024-05-06 07:41:01,214] {standard_task_runner.py:52} INFO - Started process 177 to run task
[2024-05-06 07:41:01,220] {standard_task_runner.py:76} INFO - Running: ['airflow', 'tasks', 'run', 'dag_with_prostgres_hooks_v2', 'poastgres_to_s3', '2024-05-05T00:00:00+00:00', '--job-id', '136', '--pool', 'default_pool', '--raw', '--subdir', 'DAGS_FOLDER/dag_with_postgres_hooks.py', '--cfg-path', '/tmp/tmp6lbi3fl2', '--error-file', '/tmp/tmpui69uic_']
[2024-05-06 07:41:01,227] {standard_task_runner.py:77} INFO - Job 136: Subtask poastgres_to_s3
[2024-05-06 07:41:01,315] {logging_mixin.py:104} INFO - Running <TaskInstance: dag_with_prostgres_hooks_v2.poastgres_to_s3 2024-05-05T00:00:00+00:00 [running]> on host d4a0c764ecae
[2024-05-06 07:41:01,417] {taskinstance.py:1257} INFO - Exporting the following env vars:
AIRFLOW_CTX_DAG_OWNER=Mark
AIRFLOW_CTX_DAG_ID=dag_with_prostgres_hooks_v2
AIRFLOW_CTX_TASK_ID=poastgres_to_s3
AIRFLOW_CTX_EXECUTION_DATE=2024-05-05T00:00:00+00:00
AIRFLOW_CTX_DAG_RUN_ID=scheduled__2024-05-05T00:00:00+00:00
[2024-05-06 07:41:01,445] {base.py:74} INFO - Using connection to: id: postgres_localhost. Host: host.docker.internal, Port: 5432, Schema: test, Login: airflow, Password: XXXXXXXX, extra: None
[2024-05-06 07:41:01,619] {dag_with_postgres_hooks.py:32} INFO - Saved orders data in text file: dags/get_orders_20240505.txt
[2024-05-06 07:41:01,622] {base_aws.py:362} INFO - Airflow Connection: aws_conn_id=minio_conn
[2024-05-06 07:41:01,638] {base_aws.py:164} INFO - Credentials retrieved from extra_config
[2024-05-06 07:41:01,639] {base_aws.py:81} INFO - Creating session with aws_access_key_id=ROOTUSER region_name=None
[2024-05-06 07:41:01,690] {base_aws.py:151} INFO - role_arn is None
[2024-05-06 07:41:11,960] {taskinstance.py:1455} ERROR - Could not connect to the endpoint URL: "http://host.docker.internal:9000/airflow/orders/20240505.txt"
Traceback (most recent call last):
  File "/home/airflow/.local/lib/python3.6/site-packages/urllib3/connection.py", line 160, in _new_conn
    (self._dns_host, self.port), self.timeout, **extra_kw
  File "/home/airflow/.local/lib/python3.6/site-packages/urllib3/util/connection.py", line 84, in create_connection
    raise err
  File "/home/airflow/.local/lib/python3.6/site-packages/urllib3/util/connection.py", line 74, in create_connection
    sock.connect(sa)
ConnectionRefusedError: [Errno 111] Connection refused

During handling of the above exception, another exception occurred:

Traceback (most recent call last):
  File "/home/airflow/.local/lib/python3.6/site-packages/botocore/httpsession.py", line 263, in send
    chunked=self._chunked(request.headers),
  File "/home/airflow/.local/lib/python3.6/site-packages/urllib3/connectionpool.py", line 727, in urlopen
    method, url, error=e, _pool=self, _stacktrace=sys.exc_info()[2]
  File "/home/airflow/.local/lib/python3.6/site-packages/urllib3/util/retry.py", line 386, in increment
    raise six.reraise(type(error), error, _stacktrace)
  File "/home/airflow/.local/lib/python3.6/site-packages/urllib3/packages/six.py", line 735, in reraise
    raise value
  File "/home/airflow/.local/lib/python3.6/site-packages/urllib3/connectionpool.py", line 677, in urlopen
    chunked=chunked,
  File "/home/airflow/.local/lib/python3.6/site-packages/urllib3/connectionpool.py", line 392, in _make_request
    conn.request(method, url, **httplib_request_kw)
  File "/usr/local/lib/python3.6/http/client.py", line 1291, in request
    self._send_request(method, url, body, headers, encode_chunked)
  File "/home/airflow/.local/lib/python3.6/site-packages/botocore/awsrequest.py", line 92, in _send_request
    method, url, body, headers, *args, **kwargs)
  File "/usr/local/lib/python3.6/http/client.py", line 1337, in _send_request
    self.endheaders(body, encode_chunked=encode_chunked)
  File "/usr/local/lib/python3.6/http/client.py", line 1286, in endheaders
    self._send_output(message_body, encode_chunked=encode_chunked)
  File "/home/airflow/.local/lib/python3.6/site-packages/botocore/awsrequest.py", line 119, in _send_output
    self.send(msg)
  File "/home/airflow/.local/lib/python3.6/site-packages/botocore/awsrequest.py", line 203, in send
    return super(AWSConnection, self).send(str)
  File "/usr/local/lib/python3.6/http/client.py", line 984, in send
    self.connect()
  File "/home/airflow/.local/lib/python3.6/site-packages/urllib3/connection.py", line 187, in connect
    conn = self._new_conn()
  File "/home/airflow/.local/lib/python3.6/site-packages/urllib3/connection.py", line 172, in _new_conn
    self, "Failed to establish a new connection: %s" % e
urllib3.exceptions.NewConnectionError: <botocore.awsrequest.AWSHTTPConnection object at 0x7f84987a3a58>: Failed to establish a new connection: [Errno 111] Connection refused

During handling of the above exception, another exception occurred:

Traceback (most recent call last):
  File "/home/airflow/.local/lib/python3.6/site-packages/airflow/models/taskinstance.py", line 1112, in _run_raw_task
    self._prepare_and_execute_task_with_callbacks(context, task)
  File "/home/airflow/.local/lib/python3.6/site-packages/airflow/models/taskinstance.py", line 1285, in _prepare_and_execute_task_with_callbacks
    result = self._execute_task(context, task_copy)
  File "/home/airflow/.local/lib/python3.6/site-packages/airflow/models/taskinstance.py", line 1315, in _execute_task
    result = task_copy.execute(context=context)
  File "/home/airflow/.local/lib/python3.6/site-packages/airflow/operators/python.py", line 117, in execute
    return_value = self.execute_callable()
  File "/home/airflow/.local/lib/python3.6/site-packages/airflow/operators/python.py", line 128, in execute_callable
    return self.python_callable(*self.op_args, **self.op_kwargs)
  File "/opt/airflow/dags/dag_with_postgres_hooks.py", line 39, in postgres_to_S3
    replace=True
  File "/home/airflow/.local/lib/python3.6/site-packages/airflow/providers/amazon/aws/hooks/s3.py", line 61, in wrapper
    return func(*bound_args.args, **bound_args.kwargs)
  File "/home/airflow/.local/lib/python3.6/site-packages/airflow/providers/amazon/aws/hooks/s3.py", line 90, in wrapper
    return func(*bound_args.args, **bound_args.kwargs)
  File "/home/airflow/.local/lib/python3.6/site-packages/airflow/providers/amazon/aws/hooks/s3.py", line 505, in load_file
    client.upload_file(filename, bucket_name, key, ExtraArgs=extra_args)
  File "/home/airflow/.local/lib/python3.6/site-packages/boto3/s3/inject.py", line 131, in upload_file
    extra_args=ExtraArgs, callback=Callback)
  File "/home/airflow/.local/lib/python3.6/site-packages/boto3/s3/transfer.py", line 279, in upload_file
    future.result()
  File "/home/airflow/.local/lib/python3.6/site-packages/s3transfer/futures.py", line 106, in result
    return self._coordinator.result()
  File "/home/airflow/.local/lib/python3.6/site-packages/s3transfer/futures.py", line 265, in result
    raise self._exception
  File "/home/airflow/.local/lib/python3.6/site-packages/s3transfer/tasks.py", line 126, in __call__
    return self._execute_main(kwargs)
  File "/home/airflow/.local/lib/python3.6/site-packages/s3transfer/tasks.py", line 150, in _execute_main
    return_value = self._main(**kwargs)
  File "/home/airflow/.local/lib/python3.6/site-packages/s3transfer/upload.py", line 692, in _main
    client.put_object(Bucket=bucket, Key=key, Body=body, **extra_args)
  File "/home/airflow/.local/lib/python3.6/site-packages/botocore/client.py", line 357, in _api_call
    return self._make_api_call(operation_name, kwargs)
  File "/home/airflow/.local/lib/python3.6/site-packages/botocore/client.py", line 663, in _make_api_call
    operation_model, request_dict, request_context)
  File "/home/airflow/.local/lib/python3.6/site-packages/botocore/client.py", line 682, in _make_request
    return self._endpoint.make_request(operation_model, request_dict)
  File "/home/airflow/.local/lib/python3.6/site-packages/botocore/endpoint.py", line 102, in make_request
    return self._send_request(request_dict, operation_model)
  File "/home/airflow/.local/lib/python3.6/site-packages/botocore/endpoint.py", line 137, in _send_request
    success_response, exception):
  File "/home/airflow/.local/lib/python3.6/site-packages/botocore/endpoint.py", line 256, in _needs_retry
    caught_exception=caught_exception, request_dict=request_dict)
  File "/home/airflow/.local/lib/python3.6/site-packages/botocore/hooks.py", line 356, in emit
    return self._emitter.emit(aliased_event_name, **kwargs)
  File "/home/airflow/.local/lib/python3.6/site-packages/botocore/hooks.py", line 228, in emit
    return self._emit(event_name, kwargs)
  File "/home/airflow/.local/lib/python3.6/site-packages/botocore/hooks.py", line 211, in _emit
    response = handler(**kwargs)
  File "/home/airflow/.local/lib/python3.6/site-packages/botocore/retryhandler.py", line 183, in __call__
    if self._checker(attempts, response, caught_exception):
  File "/home/airflow/.local/lib/python3.6/site-packages/botocore/retryhandler.py", line 251, in __call__
    caught_exception)
  File "/home/airflow/.local/lib/python3.6/site-packages/botocore/retryhandler.py", line 277, in _should_retry
    return self._checker(attempt_number, response, caught_exception)
  File "/home/airflow/.local/lib/python3.6/site-packages/botocore/retryhandler.py", line 317, in __call__
    caught_exception)
  File "/home/airflow/.local/lib/python3.6/site-packages/botocore/retryhandler.py", line 223, in __call__
    attempt_number, caught_exception)
  File "/home/airflow/.local/lib/python3.6/site-packages/botocore/retryhandler.py", line 359, in _check_caught_exception
    raise caught_exception
  File "/home/airflow/.local/lib/python3.6/site-packages/botocore/endpoint.py", line 200, in _do_get_response
    http_response = self._send(request)
  File "/home/airflow/.local/lib/python3.6/site-packages/botocore/endpoint.py", line 269, in _send
    return self.http_session.send(request)
  File "/home/airflow/.local/lib/python3.6/site-packages/botocore/httpsession.py", line 283, in send
    raise EndpointConnectionError(endpoint_url=request.url, error=e)
botocore.exceptions.EndpointConnectionError: Could not connect to the endpoint URL: "http://host.docker.internal:9000/airflow/orders/20240505.txt"
[2024-05-06 07:41:12,002] {taskinstance.py:1503} INFO - Marking task as UP_FOR_RETRY. dag_id=dag_with_prostgres_hooks_v2, task_id=poastgres_to_s3, execution_date=20240505T000000, start_date=20240506T074101, end_date=20240506T074112
[2024-05-06 07:41:12,112] {local_task_job.py:146} INFO - Task exited with return code 1
