[2024-05-05 13:43:56,617] {taskinstance.py:851} INFO - Dependencies all met for <TaskInstance: dag_with_prostgres_hooks_v2.poastgres_to_s3 2024-05-05T13:39:49.974301+00:00 [queued]>
[2024-05-05 13:43:56,637] {taskinstance.py:851} INFO - Dependencies all met for <TaskInstance: dag_with_prostgres_hooks_v2.poastgres_to_s3 2024-05-05T13:39:49.974301+00:00 [queued]>
[2024-05-05 13:43:56,638] {taskinstance.py:1042} INFO - 
--------------------------------------------------------------------------------
[2024-05-05 13:43:56,639] {taskinstance.py:1043} INFO - Starting attempt 3 of 6
[2024-05-05 13:43:56,640] {taskinstance.py:1044} INFO - 
--------------------------------------------------------------------------------
[2024-05-05 13:43:56,650] {taskinstance.py:1063} INFO - Executing <Task(PythonOperator): poastgres_to_s3> on 2024-05-05T13:39:49.974301+00:00
[2024-05-05 13:43:56,655] {standard_task_runner.py:52} INFO - Started process 7311 to run task
[2024-05-05 13:43:56,659] {standard_task_runner.py:76} INFO - Running: ['airflow', 'tasks', 'run', 'dag_with_prostgres_hooks_v2', 'poastgres_to_s3', '2024-05-05T13:39:49.974301+00:00', '--job-id', '66', '--pool', 'default_pool', '--raw', '--subdir', 'DAGS_FOLDER/dag_with_postgres_hooks.py', '--cfg-path', '/tmp/tmpbip2gzh3', '--error-file', '/tmp/tmpz4_dp94x']
[2024-05-05 13:43:56,662] {standard_task_runner.py:77} INFO - Job 66: Subtask poastgres_to_s3
[2024-05-05 13:43:56,713] {logging_mixin.py:104} INFO - Running <TaskInstance: dag_with_prostgres_hooks_v2.poastgres_to_s3 2024-05-05T13:39:49.974301+00:00 [running]> on host d4a0c764ecae
[2024-05-05 13:43:56,757] {taskinstance.py:1257} INFO - Exporting the following env vars:
AIRFLOW_CTX_DAG_OWNER=Mark
AIRFLOW_CTX_DAG_ID=dag_with_prostgres_hooks_v2
AIRFLOW_CTX_TASK_ID=poastgres_to_s3
AIRFLOW_CTX_EXECUTION_DATE=2024-05-05T13:39:49.974301+00:00
AIRFLOW_CTX_DAG_RUN_ID=manual__2024-05-05T13:39:49.974301+00:00
[2024-05-05 13:43:56,767] {base.py:74} INFO - Using connection to: id: postgres_localhost. Host: host.docker.internal, Port: 5432, Schema: test, Login: airflow, Password: XXXXXXXX, extra: None
[2024-05-05 13:43:56,788] {dag_with_postgres_hooks.py:32} INFO - Saved orders data in text file: dags/get_orders_20240505.txt
[2024-05-05 13:43:56,789] {base_aws.py:362} INFO - Airflow Connection: aws_conn_id=minio_conn
[2024-05-05 13:43:56,795] {base_aws.py:385} WARNING - Unable to use Airflow Connection for credentials.
[2024-05-05 13:43:56,796] {base_aws.py:386} INFO - Fallback on boto3 credential strategy
[2024-05-05 13:43:56,796] {base_aws.py:391} INFO - Creating session using boto3 credential strategy region_name=None
[2024-05-05 13:43:56,858] {taskinstance.py:1455} ERROR - Unable to locate credentials
Traceback (most recent call last):
  File "/home/airflow/.local/lib/python3.6/site-packages/airflow/models/taskinstance.py", line 1112, in _run_raw_task
    self._prepare_and_execute_task_with_callbacks(context, task)
  File "/home/airflow/.local/lib/python3.6/site-packages/airflow/models/taskinstance.py", line 1285, in _prepare_and_execute_task_with_callbacks
    result = self._execute_task(context, task_copy)
  File "/home/airflow/.local/lib/python3.6/site-packages/airflow/models/taskinstance.py", line 1315, in _execute_task
    result = task_copy.execute(context=context)
  File "/home/airflow/.local/lib/python3.6/site-packages/airflow/operators/python.py", line 117, in execute
    return_value = self.execute_callable()
  File "/home/airflow/.local/lib/python3.6/site-packages/airflow/operators/python.py", line 128, in execute_callable
    return self.python_callable(*self.op_args, **self.op_kwargs)
  File "/opt/airflow/dags/dag_with_postgres_hooks.py", line 39, in postgres_to_S3
    replace=True
  File "/home/airflow/.local/lib/python3.6/site-packages/airflow/providers/amazon/aws/hooks/s3.py", line 61, in wrapper
    return func(*bound_args.args, **bound_args.kwargs)
  File "/home/airflow/.local/lib/python3.6/site-packages/airflow/providers/amazon/aws/hooks/s3.py", line 90, in wrapper
    return func(*bound_args.args, **bound_args.kwargs)
  File "/home/airflow/.local/lib/python3.6/site-packages/airflow/providers/amazon/aws/hooks/s3.py", line 505, in load_file
    client.upload_file(filename, bucket_name, key, ExtraArgs=extra_args)
  File "/home/airflow/.local/lib/python3.6/site-packages/boto3/s3/inject.py", line 131, in upload_file
    extra_args=ExtraArgs, callback=Callback)
  File "/home/airflow/.local/lib/python3.6/site-packages/boto3/s3/transfer.py", line 279, in upload_file
    future.result()
  File "/home/airflow/.local/lib/python3.6/site-packages/s3transfer/futures.py", line 106, in result
    return self._coordinator.result()
  File "/home/airflow/.local/lib/python3.6/site-packages/s3transfer/futures.py", line 265, in result
    raise self._exception
  File "/home/airflow/.local/lib/python3.6/site-packages/s3transfer/tasks.py", line 126, in __call__
    return self._execute_main(kwargs)
  File "/home/airflow/.local/lib/python3.6/site-packages/s3transfer/tasks.py", line 150, in _execute_main
    return_value = self._main(**kwargs)
  File "/home/airflow/.local/lib/python3.6/site-packages/s3transfer/upload.py", line 692, in _main
    client.put_object(Bucket=bucket, Key=key, Body=body, **extra_args)
  File "/home/airflow/.local/lib/python3.6/site-packages/botocore/client.py", line 357, in _api_call
    return self._make_api_call(operation_name, kwargs)
  File "/home/airflow/.local/lib/python3.6/site-packages/botocore/client.py", line 663, in _make_api_call
    operation_model, request_dict, request_context)
  File "/home/airflow/.local/lib/python3.6/site-packages/botocore/client.py", line 682, in _make_request
    return self._endpoint.make_request(operation_model, request_dict)
  File "/home/airflow/.local/lib/python3.6/site-packages/botocore/endpoint.py", line 102, in make_request
    return self._send_request(request_dict, operation_model)
  File "/home/airflow/.local/lib/python3.6/site-packages/botocore/endpoint.py", line 132, in _send_request
    request = self.create_request(request_dict, operation_model)
  File "/home/airflow/.local/lib/python3.6/site-packages/botocore/endpoint.py", line 116, in create_request
    operation_name=operation_model.name)
  File "/home/airflow/.local/lib/python3.6/site-packages/botocore/hooks.py", line 356, in emit
    return self._emitter.emit(aliased_event_name, **kwargs)
  File "/home/airflow/.local/lib/python3.6/site-packages/botocore/hooks.py", line 228, in emit
    return self._emit(event_name, kwargs)
  File "/home/airflow/.local/lib/python3.6/site-packages/botocore/hooks.py", line 211, in _emit
    response = handler(**kwargs)
  File "/home/airflow/.local/lib/python3.6/site-packages/botocore/signers.py", line 90, in handler
    return self.sign(operation_name, request)
  File "/home/airflow/.local/lib/python3.6/site-packages/botocore/signers.py", line 162, in sign
    auth.add_auth(request)
  File "/home/airflow/.local/lib/python3.6/site-packages/botocore/auth.py", line 357, in add_auth
    raise NoCredentialsError
botocore.exceptions.NoCredentialsError: Unable to locate credentials
[2024-05-05 13:43:56,871] {taskinstance.py:1503} INFO - Marking task as UP_FOR_RETRY. dag_id=dag_with_prostgres_hooks_v2, task_id=poastgres_to_s3, execution_date=20240505T133949, start_date=20240505T134356, end_date=20240505T134356
[2024-05-05 13:43:56,912] {local_task_job.py:146} INFO - Task exited with return code 1
